<?xml version="1.0" ?>
<!-- =================================================================================== -->
<!-- |    This document was autogenerated by xacro from three_wheeled_robot.xacro      | -->
<!-- |    EDITING THIS FILE BY HAND IS NOT RECOMMENDED                                 | -->
<!-- =================================================================================== -->
<!-- three_wheeled_robot.xacro -->
<robot name="three_wheeled_robot">
  <!-- ROS Control plugin -->
  <gazebo>
    <plugin filename="libgazebo_ros_diff_drive.so" name="diff_drive_controller">
      <robotNamespace>/</robotNamespace>
      <commandTopic>cmd_vel</commandTopic>
      <odometryTopic>odom</odometryTopic>
      <odometryFrame>odom</odometryFrame>
      <robotBaseFrame>base_link</robotBaseFrame>
      <leftJoint>left_wheel_joint</leftJoint>
      <rightJoint>right_wheel_joint</rightJoint>
      <wheelSeparation>0.4</wheelSeparation>
      <legacyMode>false</legacyMode>
      <wheelDiameter>0.14</wheelDiameter>
      <robotBaseFrame>base_link</robotBaseFrame>
      <publishOdomTF>true</publishOdomTF>
      <publishWheelJointState>true</publishWheelJointState>
      <max_wheel_torque>20</max_wheel_torque>
      <wheelAcceleration>1</wheelAcceleration>
      <max_wheel_acceleration>1</max_wheel_acceleration>
      <wheelTorque>20</wheelTorque>
      <updateRate>50</updateRate>
      <max_velocity>0.5</max_velocity>
    </plugin>
  </gazebo>
  <material name="orange">
    <color rgba="1.0 0.423529411765 0.0392156862745 1.0"/>
  </material>
  <material name="black">
    <color rgba="0 0 0 1"/>
  </material>
  <gazebo reference="base_link">
    <material>Gazebo/Blue</material>
    <mu1 value="1.0"/>
    <mu2 value="1.0"/>
    <kp value="10000000.0"/>
    <kd value="100.0"/>
  </gazebo>
  <gazebo reference="caster_wheel">
    <mu1 value="1.0"/>
    <mu2 value="1.0"/>
    <kp value="10000000.0"/>
    <kd value="1.0"/>
    <material>Gazebo/Orange</material>
  </gazebo>
  <gazebo reference="right_wheel">
    <mu1 value="1.5"/>
    <mu2 value="1.5"/>
    <kp value="10000000.0"/>
    <kd value="1.0"/>
    <fdir1 value="1 0 0"/>
    <material>Gazebo/Black</material>
  </gazebo>
  <gazebo reference="left_wheel">
    <mu1 value="1.5"/>
    <mu2 value="1.5"/>
    <kp value="10000000.0"/>
    <kd value="1.0"/>
    <fdir1 value="1 0 0"/>
    <material>Gazebo/Black</material>
  </gazebo>
  <gazebo reference="left_wall">
    <material>Gazebo/Grey</material>
    <mu1 value="0.5"/>
    <mu2 value="0.5"/>
    <kp value="1000000.0"/>
    <kd value="100.0"/>
  </gazebo>
  <gazebo reference="right_wall">
    <material>Gazebo/Grey</material>
    <mu1 value="0.5"/>
    <mu2 value="0.5"/>
    <kp value="1000000.0"/>
    <kd value="100.0"/>
  </gazebo>
  <!-- Base Link -->
  <link name="base_link">
    <origin rpy="0 0 0" xyz="0.2 0.1 0.05"/>
    <visual>
      <geometry>
        <box size="0.35 0.4 0.05"/>
      </geometry>
      <material name="blue">
        <color rgba="0 0 1 1"/>
      </material>
    </visual>
    <collision>
      <geometry>
        <box size="0.35 0.4 0.1"/>
      </geometry>
    </collision>
    <inertial>
      <mass value="0.6"/>
      <inertia ixx="0.001" ixy="0" ixz="0" iyy="0.001" iyz="0" izz="0.001"/>
      <origin rpy="0 0 0" xyz="0 0 0"/>
    </inertial>
  </link>
  <link name="caster_wheel">
    <visual>
      <geometry>
        <sphere radius="0.02"/>
      </geometry>
      <material name="grey">
        <color rgba="0.5 0.5 0.5 1"/>
      </material>
    </visual>
    <collision>
      <geometry>
        <sphere radius="0.02"/>
      </geometry>
    </collision>
    <inertial>
      <mass value="0.3"/>
      <inertia ixx="0.00018" ixy="0" ixz="0" iyy="0.00018" iyz="0" izz="0.00018"/>
      <origin rpy="0 0 0" xyz="0 0 0"/>
    </inertial>
  </link>
  <joint name="caster_wheel_joint" type="fixed">
    <parent link="base_link"/>
    <child link="caster_wheel"/>
    <origin rpy="0 0 0" xyz="0.10606060606060606 0 -0.02"/>
    <!-- Corrected Z offset for caster wheel -->
    <dynamics damping="0.01"/>
  </joint>
  <link name="left_wheel">
    <visual>
      <geometry>
        <cylinder length="0.04" radius="0.07"/>
      </geometry>
      <material name="black">
        <color rgba="0 0 0 1"/>
      </material>
    </visual>
    <collision>
      <geometry>
        <cylinder length="0.08" radius="0.07"/>
      </geometry>
    </collision>
    <inertial>
      <mass value="1"/>
      <inertia ixx="0.0007" ixy="0" ixz="0" iyy="0.0007" iyz="0" izz="0.0007"/>
    </inertial>
  </link>
  <joint name="left_wheel_joint" type="continuous">
    <parent link="base_link"/>
    <child link="left_wheel"/>
    <origin rpy="1.5707963267948966 0 0" xyz="-0.11666666666666665 0.23500000000000001 0"/>
    <!-- Corrected RPY and Z offset -->
    <axis xyz="0 0 -1"/>
    <joint_properties damping="0.5" friction="0.5"/>
  </joint>
  <link name="right_wheel">
    <visual>
      <geometry>
        <cylinder length="0.04" radius="0.07"/>
      </geometry>
      <material name="black">
        <color rgba="0 0 0 1"/>
      </material>
    </visual>
    <collision>
      <geometry>
        <cylinder length="0.08" radius="0.07"/>
      </geometry>
    </collision>
    <inertial>
      <mass value="1"/>
      <inertia ixx="0.0007" ixy="0" ixz="0" iyy="0.0007" iyz="0" izz="0.0007"/>
    </inertial>
  </link>
  <joint name="right_wheel_joint" type="continuous">
    <parent link="base_link"/>
    <child link="right_wheel"/>
    <origin rpy="1.5707963267948966 0 0" xyz="-0.11666666666666665 -0.23500000000000001 0"/>
    <!-- Corrected RPY and Z offset -->
    <axis xyz="0 0 -1"/>
    <joint_properties damping="0.5" friction="0.5"/>
  </joint>
  <!-- <xacro:arm prefix="left" side_mult="1"/>
  <xacro:arm prefix="right" side_mult="-1"/> -->
  <link name="left_wall">
    <visual>
      <geometry>
        <box size="0.3 0.01 0.16"/>
      </geometry>
      <material name="grey">
        <color rgba="0.5 0.5 0.5 1"/>
      </material>
    </visual>
    <collision>
      <geometry>
        <box size="0.3 0.01 0.16"/>
      </geometry>
    </collision>
    <inertial>
      <mass value="0.3"/>
      <inertia ixx="0.003" ixy="0" ixz="0" iyy="0.003" iyz="0" izz="0.003"/>
    </inertial>
  </link>
  <joint name="left_wall_joint" type="fixed">
    <parent link="base_link"/>
    <child link="left_wall"/>
    <origin rpy="0 0 0" xyz="0.32499999999999996 0.20500000000000002 0.08"/>
  </joint>
  <link name="right_wall">
    <visual>
      <geometry>
        <box size="0.3 0.01 0.16"/>
      </geometry>
      <material name="grey">
        <color rgba="0.5 0.5 0.5 1"/>
      </material>
    </visual>
    <collision>
      <geometry>
        <box size="0.3 0.01 0.16"/>
      </geometry>
    </collision>
    <inertial>
      <mass value="0.3"/>
      <inertia ixx="0.003" ixy="0" ixz="0" iyy="0.003" iyz="0" izz="0.003"/>
    </inertial>
  </link>
  <joint name="right_wall_joint" type="fixed">
    <parent link="base_link"/>
    <child link="right_wall"/>
    <origin rpy="0 0 0" xyz="0.32499999999999996 -0.20500000000000002 0.08"/>
  </joint>
</robot>

